2018-06-20 01:20:37 ERROR (MainThread) [homeassistant.core] Error executing service <ServiceCall climate.set_operation_mode: entity_id=['climate.daikin'], operation_mode=cool>
Traceback (most recent call last):
  File "/usr/lib/python3.5/configparser.py", line 786, in get
    value = d[option]
  File "/usr/lib/python3.5/collections/__init__.py", line 881, in __getitem__
    return self.__missing__(key)            # support subclasses that define __missing__
  File "/usr/lib/python3.5/collections/__init__.py", line 873, in __missing__
    raise KeyError(key)
KeyError: 'mid_25'

During handling of the above exception, another exception occurred:

Traceback (most recent call last):
  File "/srv/homeassistant/lib/python3.5/site-packages/homeassistant/core.py", line 1007, in _event_to_service_call
    await service_handler.func(service_call)
  File "/srv/homeassistant/lib/python3.5/site-packages/homeassistant/components/climate/__init__.py", line 399, in async_operation_set_service
    await climate.async_set_operation_mode(operation_mode)
  File "/usr/lib/python3.5/asyncio/futures.py", line 380, in __iter__
    yield self  # This tells Task to wait for completion.
  File "/usr/lib/python3.5/asyncio/tasks.py", line 304, in _wakeup
    future.result()
  File "/usr/lib/python3.5/asyncio/futures.py", line 293, in result
    raise self._exception
  File "/usr/lib/python3.5/concurrent/futures/thread.py", line 55, in run
    result = self.fn(*self.args, **self.kwargs)
  File "/home/homeassistant/.homeassistant/custom_components/climate/broadlink.py", line 303, in set_operation_mode
    self.send_ir()
  File "/home/homeassistant/.homeassistant/custom_components/climate/broadlink.py", line 167, in send_ir
    command = self._commands_ini.get(section, value)
  File "/usr/lib/python3.5/configparser.py", line 789, in get
    raise NoOptionError(option, section)
configparser.NoOptionError: No option 'mid_25' in section: 'cool'
2018-06-20 12:07:02 ERROR (MainThread) [homeassistant.core] Error doing job: Fatal read error on socket transport
Traceback (most recent call last):
  File "/usr/lib/python3.5/asyncio/selector_events.py", line 723, in _read_ready
    data = self._sock.recv(self.max_size)
OSError: [Errno 22] Invalid argument
2018-06-20 12:07:59 ERROR (MainThread) [homeassistant.core] Error doing job: Fatal read error on socket transport
Traceback (most recent call last):
  File "/usr/lib/python3.5/asyncio/selector_events.py", line 723, in _read_ready
    data = self._sock.recv(self.max_size)
TimeoutError: [Errno 110] Connection timed out
2018-06-20 12:11:03 WARNING (MainThread) [homeassistant.components.cloud.iot] Unable to connect: Cannot connect to host cloud.hass.io:8000 ssl:None [Connect call failed ('192.168.1.1', 8000)]
2018-06-20 12:54:49 ERROR (MainThread) [homeassistant.core] Error doing job: Fatal read error on socket transport
Traceback (most recent call last):
  File "/usr/lib/python3.5/asyncio/selector_events.py", line 723, in _read_ready
    data = self._sock.recv(self.max_size)
TimeoutError: [Errno 110] Connection timed out
2018-06-20 18:28:03 ERROR (MainThread) [homeassistant.core] Error doing job: Fatal read error on socket transport
Traceback (most recent call last):
  File "/usr/lib/python3.5/asyncio/selector_events.py", line 723, in _read_ready
    data = self._sock.recv(self.max_size)
TimeoutError: [Errno 110] Connection timed out
2018-06-20 22:19:13 ERROR (MainThread) [aiohttp.access] Error in logging
Traceback (most recent call last):
  File "/srv/homeassistant/lib/python3.5/site-packages/aiohttp/helpers.py", line 502, in __get__
    return inst._cache[self.name]
KeyError: 'remote'

During handling of the above exception, another exception occurred:

Traceback (most recent call last):
  File "/srv/homeassistant/lib/python3.5/site-packages/aiohttp/helpers.py", line 466, in log
    for key, value in fmt_info:
  File "/srv/homeassistant/lib/python3.5/site-packages/aiohttp/helpers.py", line 458, in <genexpr>
    for key, method in self._methods)
  File "/srv/homeassistant/lib/python3.5/site-packages/aiohttp/helpers.py", line 416, in _format_a
    ip = request.remote
  File "/srv/homeassistant/lib/python3.5/site-packages/aiohttp/helpers.py", line 504, in __get__
    val = self.wrapped(inst)
  File "/srv/homeassistant/lib/python3.5/site-packages/aiohttp/web_request.py", line 332, in remote
    peername = self.transport.get_extra_info('peername')
  File "/usr/lib/python3.5/asyncio/sslproto.py", line 306, in get_extra_info
    return self._ssl_protocol._get_extra_info(name, default)
  File "/usr/lib/python3.5/asyncio/sslproto.py", line 546, in _get_extra_info
    return self._transport.get_extra_info(name, default)
AttributeError: 'NoneType' object has no attribute 'get_extra_info'
